<mujocoinclude>

    <!-- TORSO -->
        <body name="torso_yaw_axis_bottom" pos="0 0 0.2" euler="0 0 3.14" childclass="MPL_arm">
            <geom mesh="torso_yaw_axis_assembly_bottom-1"/>
            <body name="torso_yaw_axis_top" pos="0 0 0.0247">
                <joint axis="0 0 1" name="torso_yaw" range="-1.57 1.57" damping="50"/>
                <geom mesh="torso_yaw_axis_assembly_top-2"/>
                <body name="roll_slip_yoke_assembly" pos="-0.0001 0 0.102499" quat="0 -0.707107 0 0.707107">
                    <joint axis="0 0 -1" name="torso_pitch" range="-.785 .785" damping="50"/>
                    <geom mesh="roll_slip_yoke_assembly-3" class="MPL_arm_dark"/>
                    <body name="roll_slip_yoke_assembly_top" pos="-0.08 0 0.0001" quat="0.707107 0.707107 0 0">
                        <joint axis="0 0 -1" name="torso_roll" range="-.785 .785" damping="50"/>
                        <geom mesh="roll_slip_yoke_assembly_top-4"/>
                        <body name="upper_torso" pos="-0.058 0 0" quat="0.707107 0 0.707107 0">
                            <geom mesh="upper_torso_assembly-5" class="MPL_arm_dark"/>
                            <geom type="cylinder" size=".05 .005" pos=".035 0 -.25" euler="0 1.57 0"/>

                            <!-- RIGHT ARM -->
                            <body name="Rmpl_attach" pos="0 0.19973 -0.30578" quat="0.707107 -0.707107 0 0">
                                <geom mesh="base_linkR"/>
                                <body name="Rshoulder_link" pos="0 0 0">
                                    <joint axis="0 0 1" name="Rshoulder_fe" range="-0.611 2.792"/>
                                    <geom mesh="shoulder_linkR"/>
                                    <body name="Rhumerus_upper_link" pos="0.0016428 0 0">
                                        <joint axis="1 0 0" name="Rshoulder_abad" range="-2.792 0"/>
                                        <geom mesh="humerus_upper_linkR" class="MPL_arm_dark"/>
                                        <body name="Rhumerus_lower_link" pos="-0.0016397 -0.15007 0.013891">
                                            <joint axis="0 1 0" name="Rhumeral_rot" range="-0.524 1.483"/>
                                            <geom mesh="humerus_lower_top_linkR"/>
                                            <geom mesh="humerus_lower_bottom_linkR"/>
                                            <body name="Rforearm_link" pos="0.01 -0.14441 0.0006524">
                                                <joint axis="0 0 1" name="Relbow" range="0.05 2.356"/>
                                                <geom mesh="forearm_linkR" class="MPL_arm_dark"/>

                                                <!-- RIGHT HAND -->
                                                <include file="./../../MPL_sim/assets/simpleHandR_chain.xml"/>

                                            </body>
                                        </body>
                                    </body>
                                </body>
                            </body>

                            <!-- LEFT ARM -->
                            <body name="Lmpl_attach" pos="0 -0.19973 -0.30578" quat="0.707107 -0.707107 0 0">
                                <geom mesh="base_linkL"/>
                                <body name="Lshoulder_link" pos="0 0 0">
                                    <joint axis="0 0 1" name="Lshoulder_fe" range="-0.611 2.792"/>
                                    <geom mesh="shoulder_linkL"/>
                                    <body name="Lhumerus_upper_link" pos="0.0016428 0 0">
                                        <joint axis="-1 0 0" name="Lshoulder_abad" range="-2.792 0"/>
                                        <geom mesh="humerus_upper_linkL" class="MPL_arm_dark"/>
                                        <body name="Lhumerus_lower_link" pos="-0.0016397 -0.15007 -0.013891">
                                            <joint axis="0 -1 0" name="Lhumeral_rot" range="-0.524 1.483"/>
                                            <geom mesh="humerus_lower_top_linkL"/>
                                            <geom mesh="humerus_lower_bottom_linkL"/>
                                            <body name="Lforearm_link" pos="0.01 -0.14441 -0.0006524">
                                                <joint axis="0 0 1" name="Lelbow" range="0.05 2.356"/>
                                                <geom mesh="forearm_linkL" class="MPL_arm_dark"/>

                                                <!-- LEFT HAND -->
                                                <include file="./../../MPL_sim/assets/simpleHandL_chain.xml"/>

                                            </body>
                                        </body>
                                    </body>
                                </body>
                            </body>

                        </body>
                    </body>
                </body>
            </body>
        </body>

</mujocoinclude>